<?xml version="1.0" encoding="utf-8"?>
<!-- This URDF was automatically created by SolidWorks to URDF Exporter! Originally created by Stephen Brawner (brawner@gmail.com) 
     Commit Version: 1.6.0-4-g7f85cfe  Build Version: 1.6.7995.38578
     For more information, please see http://wiki.ros.org/sw_urdf_exporter -->
<robot
  name="engineer2023">
  <link
    name="base_link">
    <inertial>
      <origin
        xyz="0.00860855472728023 -0.00437039461327193 0.294363549670489"
        rpy="0 0 0" />
      <mass
        value="5.36255438288469" />
      <inertia
        ixx="0.0368689054288341"
        ixy="1.06932302914025E-07"
        ixz="-4.51245253411176E-07"
        iyy="0.034567058594997"
        iyz="-1.64530978478844E-05"
        izz="0.0333320226083151" />
    </inertial>
    <visual>
      <origin
        xyz="0 0 0"
        rpy="0 0 0" />
      <geometry>
        <mesh
          filename="package://description/meshes/base_link.STL" />
      </geometry>
      <material
        name="">
        <color
          rgba="1 1 1 1" />
      </material>
    </visual>
    <collision>
      <origin
        xyz="0 0 0"
        rpy="0 0 0" />
      <geometry>
        <mesh
          filename="package://description/meshes/base_link.STL" />
      </geometry>
    </collision>
  </link>
  <link
    name="link1">
    <inertial>
      <origin
        xyz="-0.0670299889949109 0.496073026085852 0.235466039788702"
        rpy="0 0 0" />
      <mass
        value="1.8899542899265" />
      <inertia
        ixx="0.0248688762406123"
        ixy="-4.42067255445509E-17"
        ixz="-9.67418184000422E-07"
        iyy="0.0188121866750527"
        iyz="2.37521059847883E-07"
        izz="0.00721822757815201" />
    </inertial>
    <visual>
      <origin
        xyz="0 0 0"
        rpy="0 0 0" />
      <geometry>
        <mesh
          filename="package://description/meshes/link1.STL" />
      </geometry>
      <material
        name="">
        <color
          rgba="1 1 1 1" />
      </material>
    </visual>
    <collision>
      <origin
        xyz="0 0 0"
        rpy="0 0 0" />
      <geometry>
        <mesh
          filename="package://description/meshes/link1.STL" />
      </geometry>
    </collision>
  </link>
  <joint
    name="joint1"
    type="prismatic">
    <origin
      xyz="0.069945 -0.51446 0.1115"
      rpy="0 0 0" />
    <parent
      link="base_link" />
    <child
      link="link1" />
    <axis
      xyz="0 0 1" />
    <limit
      lower="0"
      upper="0.485"
      effort="0"
      velocity="0.2" />
  </joint>
  <link
    name="link2">
    <inertial>
      <origin
        xyz="-0.069064167255025 -0.164686796320371 0.559983901148351"
        rpy="0 0 0" />
      <mass
        value="0.465775740431193" />
      <inertia
        ixx="0.00554341116259535"
        ixy="1.08839452898242E-20"
        ixz="-7.27057285792211E-17"
        iyy="0.0055344313436651"
        iyz="6.57504195748452E-06"
        izz="2.55044948028102E-05" />
    </inertial>
    <visual>
      <origin
        xyz="0 0 0"
        rpy="0 0 0" />
      <geometry>
        <mesh
          filename="package://description/meshes/link2.STL" />
      </geometry>
      <material
        name="">
        <color
          rgba="1 1 1 1" />
      </material>
    </visual>
    <collision>
      <origin
        xyz="0 0 0"
        rpy="0 0 0" />
      <geometry>
        <mesh
          filename="package://description/meshes/link2.STL" />
      </geometry>
    </collision>
  </link>
  <joint
    name="joint2"
    type="prismatic">
    <origin
      xyz="0 0 0"
      rpy="-1.5708 0 0" />
    <parent
      link="link1" />
    <child
      link="link2" />
    <axis
      xyz="0 0 1" />
    <limit
      lower="0"
      upper="0.36"
      effort="0"
      velocity="0.2" />
  </joint>
  <link
    name="link3">
    <inertial>
      <origin
        xyz="-0.0624844955825998 0.173018929399761 -0.732875937421561"
        rpy="0 0 0" />
      <mass
        value="0.63757668613832" />
      <inertia
        ixx="0.000122153871392879"
        ixy="-8.31106451957901E-06"
        ixz="-6.89789081781398E-06"
        iyy="0.00337581247074143"
        iyz="-4.26243599004247E-06"
        izz="0.00332932083394479" />
    </inertial>
    <visual>
      <origin
        xyz="0 0 0"
        rpy="0 0 0" />
      <geometry>
        <mesh
          filename="package://description/meshes/link3.STL" />
      </geometry>
      <material
        name="">
        <color
          rgba="0.603921568627451 0.603921568627451 0.603921568627451 1" />
      </material>
    </visual>
    <collision>
      <origin
        xyz="0 0 0"
        rpy="0 0 0" />
      <geometry>
        <mesh
          filename="package://description/meshes/link3.STL" />
      </geometry>
    </collision>
  </link>
  <joint
    name="joint3"
    type="prismatic">
    <origin
      xyz="0 0 0"
      rpy="3.1416 0 0" />
    <parent
      link="link2" />
    <child
      link="link3" />
    <axis
      xyz="0 0 1" />
    <limit
      lower="0"
      upper="0.315"
      effort="0"
      velocity="0.15" />
  </joint>
  <link
    name="link4">
    <inertial>
      <origin
        xyz="0.763803090901162 0.217717680052702 -0.174005198592291"
        rpy="0 0 0" />
      <mass
        value="0.131998325592955" />
      <inertia
        ixx="0.000114655778117915"
        ixy="8.68441990426106E-08"
        ixz="-5.37551207080405E-08"
        iyy="0.000123899057040022"
        iyz="1.68301885402415E-07"
        izz="5.42781065796261E-05" />
    </inertial>
    <visual>
      <origin
        xyz="0 0 0"
        rpy="0 0 0" />
      <geometry>
        <mesh
          filename="package://description/meshes/link4.STL" />
      </geometry>
      <material
        name="">
        <color
          rgba="0.792156862745098 0.819607843137255 0.933333333333333 1" />
      </material>
    </visual>
    <collision>
      <origin
        xyz="0 0 0"
        rpy="0 0 0" />
      <geometry>
        <mesh
          filename="package://description/meshes/link4.STL" />
      </geometry>
    </collision>
  </link>
  <joint
    name="joint4"
    type="prismatic">
    <origin
      xyz="0 0 0"
      rpy="0 1.5708 0" />
    <parent
      link="link3" />
    <child
      link="link4" />
    <axis
      xyz="0 0 1" />
    <limit
      lower="0"
      upper="0.185"
      effort="0"
      velocity="0.15" />
  </joint>
  <link
    name="link5">
    <inertial>
      <origin
        xyz="5.55111512312578E-17 0.0174395989021934 0.0252245607121308"
        rpy="0 0 0" />
      <mass
        value="0.120245289388468" />
      <inertia
        ixx="7.97670405138728E-05"
        ixy="1.83812739380579E-20"
        ixz="3.55696411763409E-20"
        iyy="8.70447786854997E-05"
        iyz="-1.42203223229367E-07"
        izz="0.000147773300082745" />
    </inertial>
    <visual>
      <origin
        xyz="0 0 0"
        rpy="0 0 0" />
      <geometry>
        <mesh
          filename="package://description/meshes/link5.STL" />
      </geometry>
      <material
        name="">
        <color
          rgba="1 1 1 1" />
      </material>
    </visual>
    <collision>
      <origin
        xyz="0 0 0"
        rpy="0 0 0" />
      <geometry>
        <mesh
          filename="package://description/meshes/link5.STL" />
      </geometry>
    </collision>
  </link>
  <joint
    name="joint5"
    type="revolute">
    <origin
      xyz="0.80725 0.22497 -0.17472"
      rpy="0 1.5708 0" />
    <parent
      link="link4" />
    <child
      link="link5" />
    <axis
      xyz="0 0 -1" />
    <limit
      lower="-1.5708"
      upper="3.1416"
      effort="0"
      velocity="3.1416" />
  </joint>
  <link
    name="link6">
    <inertial>
      <origin
        xyz="-0.0411960122649075 0.000451135337167785 0.0342031843440899"
        rpy="0 0 0" />
      <mass
        value="0.0892340388435486" />
      <inertia
        ixx="4.10415605433343E-05"
        ixy="2.16951354427165E-08"
        ixz="3.82152872390369E-09"
        iyy="7.97730155188878E-05"
        iyz="7.63397722769667E-08"
        izz="6.67032531523372E-05" />
    </inertial>
    <visual>
      <origin
        xyz="0 0 0"
        rpy="0 0 0" />
      <geometry>
        <mesh
          filename="package://description/meshes/link6.STL" />
      </geometry>
      <material
        name="">
        <color
          rgba="1 1 1 1" />
      </material>
    </visual>
    <collision>
      <origin
        xyz="0 0 0"
        rpy="0 0 0" />
      <geometry>
        <mesh
          filename="package://description/meshes/link6.STL" />
      </geometry>
    </collision>
  </link>
  <joint
    name="joint6"
    type="revolute">
    <origin
      xyz="0 0.068 0.029"
      rpy="-1.5708 0 0" />
    <parent
      link="link5" />
    <child
      link="link6" />
    <axis
      xyz="0 0 -1" />
    <limit
      lower="-1.5708"
      upper="1.5708"
      effort="0"
      velocity="3.1416" />
  </joint>
  <link
    name="link7">
    <inertial>
      <origin
        xyz="0.00107642493785343 0.0170320435131422 0.0688632421437033"
        rpy="0 0 0" />
      <mass
        value="0.054803438385904" />
      <inertia
        ixx="2.91468111443818E-05"
        ixy="-1.90274398478157E-09"
        ixz="-3.20056133419366E-13"
        iyy="3.09646333818237E-05"
        iyz="-1.4642367828273E-09"
        izz="2.07333652050033E-05" />
    </inertial>
    <visual>
      <origin
        xyz="0 0 0"
        rpy="0 0 0" />
      <geometry>
        <mesh
          filename="package://description/meshes/link7.STL" />
      </geometry>
      <material
        name="">
        <color
          rgba="1 1 1 1" />
      </material>
    </visual>
    <collision>
      <origin
        xyz="0 0 0"
        rpy="0 0 0" />
      <geometry>
        <mesh
          filename="package://description/meshes/link7.STL" />
      </geometry>
    </collision>
  </link>
  <joint
    name="joint7"
    type="revolute">
    <origin
      xyz="0.07 0 0.054"
      rpy="1.5708 0 -1.5708" />
    <parent
      link="link6" />
    <child
      link="link7" />
    <axis
      xyz="0 0 1" />
    <limit
      lower="-1.5708"
      upper="1.5708"
      effort="0"
      velocity="3.1416" />
  </joint>
  <link
    name="link8">
    <inertial>
      <origin
        xyz="-2.4980018054066E-16 1.11022302462516E-16 -0.001"
        rpy="0 0 0" />
      <mass
        value="0.0245667847957228" />
      <inertia
        ixx="9.93636525245484E-06"
        ixy="6.69916866760257E-11"
        ixz="4.3595600698372E-20"
        iyy="4.0087869499324E-05"
        iyz="5.78187192686943E-20"
        izz="5.00078568952484E-05" />
    </inertial>
    <visual>
      <origin
        xyz="0 0 0"
        rpy="0 0 0" />
      <geometry>
        <mesh
          filename="package://description/meshes/link8.STL" />
      </geometry>
      <material
        name="">
        <color
          rgba="1 1 1 1" />
      </material>
    </visual>
    <collision>
      <origin
        xyz="0 0 0"
        rpy="0 0 0" />
      <geometry>
        <mesh
          filename="package://description/meshes/link8.STL" />
      </geometry>
    </collision>
  </link>
  <joint
    name="joint8"
    type="fixed">
    <origin
      xyz="0.0018959 0.049 0.069974"
      rpy="1.5708 -1.5708 0" />
    <parent
      link="link7" />
    <child
      link="link8" />
    <axis
      xyz="0 0 1" />
  </joint>
</robot>