<?xml version="1.0" encoding="utf-8"?>
<!-- This URDF was automatically created by SolidWorks to URDF Exporter! Originally created by Stephen Brawner (brawner@gmail.com) 
     Commit Version: 1.6.0-4-g7f85cfe  Build Version: 1.6.7995.38578
     For more information, please see http://wiki.ros.org/sw_urdf_exporter -->
<robot
  name="engineer2023">
  <link
    name="base_link">
    <inertial>
      <origin
        xyz="-0.00179259237097801 -0.0545784017542508 0.197324915291547"
        rpy="0 0 0" />
      <mass
        value="3.93247154506623" />
      <inertia
        ixx="0.0119359098908216"
        ixy="-1.29088752871052E-06"
        ixz="2.02871303899683E-08"
        iyy="0.0163355878727232"
        iyz="3.37641551535372E-08"
        izz="0.0183109062288966" />
    </inertial>
    <visual>
      <origin
        xyz="0 0 0"
        rpy="0 0 0" />
      <geometry>
        <mesh
          filename="package://description/meshes/base_link.STL" />
      </geometry>
      <material
        name="">
        <color
          rgba="1 1 1 1" />
      </material>
    </visual>
    <collision>
      <origin
        xyz="0 0 0"
        rpy="0 0 0" />
      <geometry>
        <mesh
          filename="package://description/meshes/base_link.STL" />
      </geometry>
    </collision>
  </link>
  <link
    name="link1">
    <inertial>
      <origin
        xyz="0.0691100199564756 -0.520579420808764 0.223420667670475"
        rpy="0 0 0" />
      <mass
        value="2.34054483752411" />
      <inertia
        ixx="0.0271370929244571"
        ixy="-2.53992021409299E-08"
        ixz="9.67418184004431E-07"
        iyy="0.0188825040096326"
        iyz="-3.3815357871531E-07"
        izz="0.00947835809702743" />
    </inertial>
    <visual>
      <origin
        xyz="0 0 0"
        rpy="0 0 0" />
      <geometry>
        <mesh
          filename="package://description/meshes/link1.STL" />
      </geometry>
      <material
        name="">
        <color
          rgba="1 1 1 1" />
      </material>
    </visual>
    <collision>
      <origin
        xyz="0 0 0"
        rpy="0 0 0" />
      <geometry>
        <mesh
          filename="package://description/meshes/link1.STL" />
      </geometry>
    </collision>
  </link>
  <joint
    name="joint1"
    type="prismatic">
    <origin
      xyz="0.069945 -0.51446 0.1115"
      rpy="0 0 3.1416" />
    <parent
      link="base_link" />
    <child
      link="link1" />
    <axis
      xyz="0 0 1" />
    <limit
      lower="0"
      upper="0.48"
      effort="0"
      velocity="0.2" />
  </joint>
  <link
    name="link2">
    <inertial>
      <origin
        xyz="0.0716788201187239 0.168756886268322 0.535470408809683"
        rpy="0 0 0" />
      <mass
        value="0.60180055211582" />
      <inertia
        ixx="0.00704867079984699"
        ixy="-3.05621730226656E-20"
        ixz="1.14740617228878E-16"
        iyy="0.00704736135851011"
        iyz="-3.48104532430249E-06"
        izz="2.09714081393746E-05" />
    </inertial>
    <visual>
      <origin
        xyz="0 0 0"
        rpy="0 0 0" />
      <geometry>
        <mesh
          filename="package://description/meshes/link2.STL" />
      </geometry>
      <material
        name="">
        <color
          rgba="1 1 1 1" />
      </material>
    </visual>
    <collision>
      <origin
        xyz="0 0 0"
        rpy="0 0 0" />
      <geometry>
        <mesh
          filename="package://description/meshes/link2.STL" />
      </geometry>
    </collision>
  </link>
  <joint
    name="joint2"
    type="prismatic">
    <origin
      xyz="0 0 0"
      rpy="1.5708 0 0" />
    <parent
      link="link1" />
    <child
      link="link2" />
    <axis
      xyz="0 0 1" />
    <limit
      lower="0"
      upper="0.35"
      effort="0"
      velocity="0.15" />
  </joint>
  <link
    name="link3">
    <inertial>
      <origin
        xyz="-0.0626567899671766 0.179013248842419 -0.731884378956393"
        rpy="0 0 0" />
      <mass
        value="0.655582856876397" />
      <inertia
        ixx="0.000128606135231925"
        ixy="-8.31106438494595E-06"
        ixz="-6.89789065811095E-06"
        iyy="0.00337909025926416"
        iyz="-4.26243590160401E-06"
        izz="0.00333259240886283" />
    </inertial>
    <visual>
      <origin
        xyz="0 0 0"
        rpy="0 0 0" />
      <geometry>
        <mesh
          filename="package://description/meshes/link3.STL" />
      </geometry>
      <material
        name="">
        <color
          rgba="1 1 1 1" />
      </material>
    </visual>
    <collision>
      <origin
        xyz="0 0 0"
        rpy="0 0 0" />
      <geometry>
        <mesh
          filename="package://description/meshes/link3.STL" />
      </geometry>
    </collision>
  </link>
  <joint
    name="joint3"
    type="prismatic">
    <origin
      xyz="0 0 0"
      rpy="3.1416 0 3.1416" />
    <parent
      link="link2" />
    <child
      link="link3" />
    <axis
      xyz="0 0 1" />
    <limit
      lower="0"
      upper="0.315"
      effort="0"
      velocity="0.15" />
  </joint>
  <link
    name="link4">
    <inertial>
      <origin
        xyz="0.7682596199874 0.223998163096944 -0.173425746621559"
        rpy="0 0 0" />
      <mass
        value="0.126669555017613" />
      <inertia
        ixx="0.000102701865528704"
        ixy="-6.17656822544913E-10"
        ixz="2.51540324416471E-09"
        iyy="0.00011560060672507"
        iyz="3.56134265572546E-07"
        izz="5.03755005411688E-05" />
    </inertial>
    <visual>
      <origin
        xyz="0 0 0"
        rpy="0 0 0" />
      <geometry>
        <mesh
          filename="package://description/meshes/link4.STL" />
      </geometry>
      <material
        name="">
        <color
          rgba="1 1 1 1" />
      </material>
    </visual>
    <collision>
      <origin
        xyz="0 0 0"
        rpy="0 0 0" />
      <geometry>
        <mesh
          filename="package://description/meshes/link4.STL" />
      </geometry>
    </collision>
  </link>
  <joint
    name="joint4"
    type="prismatic">
    <origin
      xyz="0 0 0"
      rpy="0 1.5708 0" />
    <parent
      link="link3" />
    <child
      link="link4" />
    <axis
      xyz="0 0 1" />
    <limit
      lower="0"
      upper="0.185"
      effort="0"
      velocity="0.1" />
  </joint>
  <link
    name="link5">
    <inertial>
      <origin
        xyz="-4.71844785465692E-16 0.0174395989021913 0.0252245607121312"
        rpy="0 0 0" />
      <mass
        value="0.120245289388468" />
      <inertia
        ixx="7.97670405138728E-05"
        ixy="9.10378082162622E-21"
        ixz="3.26865474117378E-20"
        iyy="8.70447786854997E-05"
        iyz="-1.42203223229392E-07"
        izz="0.000147773300082745" />
    </inertial>
    <visual>
      <origin
        xyz="0 0 0"
        rpy="0 0 0" />
      <geometry>
        <mesh
          filename="package://description/meshes/link5.STL" />
      </geometry>
      <material
        name="">
        <color
          rgba="1 1 1 1" />
      </material>
    </visual>
    <collision>
      <origin
        xyz="0 0 0"
        rpy="0 0 0" />
      <geometry>
        <mesh
          filename="package://description/meshes/link5.STL" />
      </geometry>
    </collision>
  </link>
  <joint
    name="joint5"
    type="revolute">
    <origin
      xyz="0.80725 0.23016 -0.15522"
      rpy="0 1.5708 0" />
    <parent
      link="link4" />
    <child
      link="link5" />
    <axis
      xyz="0 0 -1" />
    <limit
      lower="-1.5708"
      upper="3.1416"
      effort="0"
      velocity="3.1416" />
  </joint>
  <link
    name="link6">
    <inertial>
      <origin
        xyz="-0.0408986995157307 0.00039301582486273 0.0361413912810762"
        rpy="0 0 0" />
      <mass
        value="0.104211436138975" />
      <inertia
        ixx="4.46945190098756E-05"
        ixy="2.16955666600879E-08"
        ixz="4.74658523749477E-09"
        iyy="8.24613796085385E-05"
        iyz="7.63099230328579E-08"
        izz="6.80832747245119E-05" />
    </inertial>
    <visual>
      <origin
        xyz="0 0 0"
        rpy="0 0 0" />
      <geometry>
        <mesh
          filename="package://description/meshes/link6.STL" />
      </geometry>
      <material
        name="">
        <color
          rgba="1 1 1 1" />
      </material>
    </visual>
    <collision>
      <origin
        xyz="0 0 0"
        rpy="0 0 0" />
      <geometry>
        <mesh
          filename="package://description/meshes/link6.STL" />
      </geometry>
    </collision>
  </link>
  <joint
    name="joint6"
    type="revolute">
    <origin
      xyz="0 0.068 0.029"
      rpy="-1.5708 0 0" />
    <parent
      link="link5" />
    <child
      link="link6" />
    <axis
      xyz="0 0 -1" />
    <limit
      lower="-1.5708"
      upper="1.5708"
      effort="0"
      velocity="3.1416" />
  </joint>
  <link
    name="link7">
    <inertial>
      <origin
        xyz="-0.00161064391896037 0.0420362624442913 -0.0712676005006918"
        rpy="0 0 0" />
      <mass
        value="0.176077223035249" />
      <inertia
        ixx="0.000100797935050055"
        ixy="1.74924315613145E-08"
        ixz="6.80518229873215E-11"
        iyy="0.000117336537549598"
        iyz="1.46417328612756E-09"
        izz="5.74951814260827E-05" />
    </inertial>
    <visual>
      <origin
        xyz="0 0 0"
        rpy="0 0 0" />
      <geometry>
        <mesh
          filename="package://description/meshes/link7.STL" />
      </geometry>
      <material
        name="">
        <color
          rgba="1 1 1 1" />
      </material>
    </visual>
    <collision>
      <origin
        xyz="0 0 0"
        rpy="0 0 0" />
      <geometry>
        <mesh
          filename="package://description/meshes/link7.STL" />
      </geometry>
    </collision>
  </link>
  <joint
    name="joint7"
    type="revolute">
    <origin
      xyz="0.07 0 0.054"
      rpy="1.5708 0 1.5708" />
    <parent
      link="link6" />
    <child
      link="link7" />
    <axis
      xyz="0 0 -1" />
    <limit
      lower="-1.5708"
      upper="1.5708"
      effort="0"
      velocity="3.1416" />
  </joint>
  <link
    name="link8">
    <inertial>
      <origin
        xyz="-0.00185534248903982 -0.000400492513327855 0.00192915490643331"
        rpy="0 0 0" />
      <mass
        value="3.28857056779525" />
      <inertia
        ixx="0.0291697788141165"
        ixy="7.88358155297304E-08"
        ixz="4.57779349627165E-07"
        iyy="0.0289386260304365"
        iyz="3.37999755290636E-08"
        izz="0.0291701026812406" />
    </inertial>
    <visual>
      <origin
        xyz="0 0 0"
        rpy="0 0 0" />
      <geometry>
        <mesh
          filename="package://description/meshes/link8.STL" />
      </geometry>
      <material
        name="">
        <color
          rgba="1 1 0 1" />
      </material>
    </visual>
    <collision>
      <origin
        xyz="0 0 0"
        rpy="0 0 0" />
      <geometry>
        <mesh
          filename="package://description/meshes/link8.STL" />
      </geometry>
    </collision>
  </link>
  <joint
    name="joint8"
    type="fixed">
    <origin
      xyz="-0.022609 0.16849 -0.071802"
      rpy="1.5658 1.5708 3.1357" />
    <parent
      link="link7" />
    <child
      link="link8" />
    <axis
      xyz="0 0 1" />
  </joint>
</robot>